Workbook
Name rFecha: 'Registro'!$B$6:$B$5005
Name rTipo: 'Registro'!$C$6:$C$5005
Name rCat: 'Registro'!$D$6:$D$5005
Name rSub: 'Registro'!$E$6:$E$5005
Name rDesc: 'Registro'!$F$6:$F$5005
Name rMonto: 'Registro'!$G$6:$G$5005
Name rMon: 'Registro'!$H$6:$H$5005
Name rTasa: 'Registro'!$I$6:$I$5005
Name rCta: 'Registro'!$J$6:$J$5005
Name rDest: 'Registro'!$K$6:$K$5005
Name rCom: 'Registro'!$L$6:$L$5005
Name rClas: 'Registro'!$M$6:$M$5005
Name rObs: 'Registro'!$N$6:$N$5005
Name rEstado: 'Registro'!$O$6:$O$5005
Name rTipoE: 'Registro'!$P$6:$P$5005
Name rCtaE: 'Registro'!$Q$6:$Q$5005
Name rTasaRef: 'Registro'!$R$6:$R$5005
Name rDOP: 'Registro'!$S$6:$S$5005
Name rUSD: 'Registro'!$T$6:$T$5005
Name rGasto: 'Registro'!$U$6:$U$5005
Name rIng: 'Registro'!$V$6:$V$5005
Name rTrad: 'Registro'!$W$6:$W$5005
Name rClasE: 'Registro'!$X$6:$X$5005
Name rGrupo: 'Registro'!$Y$6:$Y$5005
Name rDia: 'Registro'!$Z$6:$Z$5005
Name rHorm: 'Registro'!$AA$6:$AA$5005
Name rCtaSO: 'Registro'!$AB$6:$AB$5005
Name rCtaSD: 'Registro'!$AC$6:$AC$5005
Name rTCO: 'Registro'!$AD$6:$AD$5005
Name rTCD: 'Registro'!$AE$6:$AE$5005
Name rEfO: 'Registro'!$AF$6:$AF$5005
Name rEfD: 'Registro'!$AG$6:$AG$5005
Name rFlujo: 'Registro'!$AH$6:$AH$5005
Name rComIdx: 'Registro'!$AI$6:$AI$5005
Name catCat: 'Categorías'!$B$6:$B$205
Name catSub: 'Categorías'!$C$6:$C$205
Name catTipo: 'Categorías'!$D$6:$D$205
Name catClasif: 'Categorías'!$E$6:$E$205
Name catGrupo: 'Categorías'!$F$6:$F$205
Name catComida: 'Categorías'!$G$6:$G$205
Name catClave: 'Categorías'!$P$6:$P$205
Name catIdx: 'Categorías'!$Q$6:$Q$205
Name catFoodIdx: 'Categorías'!$R$6:$R$205
Name catUList: 'Categorías'!$L$6:$L$45
Name lstCat: OFFSET('Categorías'!$L$6,0,0,MAX(1,COUNTIF('Categorías'!$L$6:$L$45,"?*")),1)
Name ctaNombre: 'Cuentas'!$B$7:$B$36
Name ctaTipo: 'Cuentas'!$C$7:$C$36
Name ctaMoneda: 'Cuentas'!$D$7:$D$36
Name ctaVinc: 'Cuentas'!$E$7:$E$36
Name ctaIni: 'Cuentas'!$F$7:$F$36
Name ctaFechaIni: 'Cuentas'!$G$7:$G$36
Name ctaLiq: 'Cuentas'!$I$7:$I$36
Name ctaMov: 'Cuentas'!$J$7:$J$36
Name ctaSaldo: 'Cuentas'!$K$7:$K$36
Name ctaSaldoDOP: 'Cuentas'!$L$7:$L$36
Name lstCuentas: OFFSET('Cuentas'!$B$7,0,0,MAX(1,COUNTIF('Cuentas'!$B$7:$B$36,"?*")),1)
Name TasaUSD: 'Config'!$C$5
Name CuentaPred: 'Config'!$C$6
Name catAlim: 'Config'!$C$7
Name catTrading: 'Config'!$C$8

Sheet Inicio
B1: Finanzas Personales | H1: Excel 365 · sin macros · moneda base DOP
B2: ● Inicio | C2: Registro | D2: Dashboard | E2: Alimentación | F2: Hormiga | G2: Recurrentes | H2: Presupuestos | I2: Cuentas | J2: Categorías | K2: Config
B4: Registra cada movimiento en segundos, entiende a dónde va tu dinero y, cuando tengas datos suficientes, define límites y metas. Todas las cifras se recalculan automáticamente al agregar filas en «Registro».
B7: Ir a…
B8: Registrar movimientos → | E8: Dashboard → | H8: Alimentación → | K8: Gastos hormiga →
B9: Una fila por transacción. Fecha + monto + categoría + cuenta. | E9: KPIs, filtros, gráficos, top 10 y comparación mensual. | H9: Comer fuera vs. cocinar, costos por comida y simulador. | K9: Consumos pequeños y frecuentes y su peso real.
B12: Suscripciones → | E12: Presupuestos y metas → | H12: Cuentas → | K12: Categorías →
B13: Agenda de cobros recurrentes y próximos vencimientos. | E13: Etapa 2: límites, alertas, fondo de emergencia, boda, inversión. | H13: Saldos iniciales, saldo actual, conciliación y deuda de tarjetas. | K13: Edita, agrega o elimina categorías y subcategorías.
B16: Estado del sistema | I16: Primeros pasos
B17: Movimientos registrados | F17: =COUNTIF(rTipoE,"?*") | I17: 1. Explora el Dashboard con los datos DEMO (filas lilas del Registro).
B18: Filas de DEMOSTRACIÓN | F18: =COUNTIF(rObs,"DEMOSTRACIÓN") | I18: 2. Borra los DEMO (ver «Eliminar datos de demostración» abajo).
B19: Filas con advertencias | F19: =COUNTIF(rEstado,"⚠*") | I19: 3. En Cuentas, renombra tus cuentas/tarjetas y, si quieres saldos reales, escribe saldo inicial y su fecha.
B20: Último movimiento | F20: =IF(COUNT(rFecha)=0,"—",MAX(rFecha)) | I20: 4. En Config, actualiza la tasa USD→DOP.
B21: Capacidad usada del Registro | F21: =COUNTA(rFecha)/5000 | I21: 5. Ajusta Categorías a tu gusto (opcional).
B22: Cuentas con saldo inicial | F22: ='Cuentas'!L41 | I22: 6. Registra cada gasto el mismo día: ~10 segundos por fila.
B23: Tasa USD→DOP en uso | F23: =TasaUSD | I23: 7. Tras 2–3 meses, revisa Alimentación y Hormiga y define límites en Presupuestos.
B24: Suscripciones que vencen en ≤ 7 días | F24: =recProximos
B26: Cómo registrar (reglas que evitan duplicar)
B27: Gasto cotidiano | E27: Fecha · (Tipo vacío = Gasto) · Categoría · Subcategoría · Monto · Cuenta. Comercio y descripción son opcionales.
B28: Compra con tarjeta de crédito | E28: Regístrala como Gasto en la fecha de consumo, con Cuenta = la tarjeta. Así el gasto cuenta una sola vez y la deuda de la tarjeta crece.
B29: Pago de la tarjeta | E29: Tipo «Pago tarjeta», Cuenta = banco que paga, Cuenta destino = la tarjeta. NO es gasto: solo reduce la deuda y sale dinero del banco.
B30: Transferencias propias | E30: Tipo «Transferencia» (banco→efectivo, banco→billetera…). No suma ni a ingresos ni a gastos; solo mueve saldos.
B31: Trading | E31: Depósito o retiro = Transferencia hacia/desde la cuenta de trading. Ganancia o pérdida realizada = «Resultado trading» (+/−). Evaluaciones, plataformas y comisiones = Gasto en la categoría de trading.
B32: Reembolsos | E32: Si te devuelven dinero, usa «Reembolso» con la misma categoría del gasto original: el gasto neto se reduce.
B33: Dólares | E33: Moneda USD. Si conoces la tasa real aplicada, escríbela en «Tasa USD»; si no, se usa la de Config. Todos los reportes salen en DOP.
B34: Ajustes | E34: Si el saldo real no coincide con el calculado (Cuentas › Conciliación), registra un «Ajuste» por la diferencia.
B36: Eliminar datos de demostración
B37: • Las filas DEMO están juntas al inicio del Registro (filas 6 a 194), marcadas «DEMOSTRACIÓN» en Observaciones y con fondo lila.
B38: • Opción rápida: en Registro selecciona B6:N194 y pulsa Suprimir. Las fórmulas automáticas (columnas O en adelante) no se tocan.
B39: • En Recurrentes, borra igual las filas marcadas «DEMOSTRACIÓN» (columnas B:L).
B40: • Las cuentas y categorías de ejemplo NO son datos personales: renómbralas o bórralas. No hay saldos ni límites precargados.
B41: • Cuando el estado de arriba muestre 0 filas DEMO, todo el sistema queda listo con tus datos.
B43: Buenas prácticas
B44: • No insertes columnas dentro de la tabla del Registro ni escribas sobre las columnas grises: son el motor del sistema.
B45: • El Registro tiene capacidad para 5,000 filas. Si te acercas al límite, selecciona la última fila completa y arrastra el controlador de la tabla hacia abajo para ampliarla.
B46: • Puedes ordenar y filtrar la tabla (flechas del encabezado) sin romper nada. Filtra la columna Estado por «⚠» para corregir errores.
B47: • Celdas amarillas = editables. Celdas grises = cálculo automático. Filas lilas = demostración.
B48: • En el celular: abre el archivo con la app de Excel (OneDrive) y registra desde la hoja Registro.

Sheet Registro
B1: Registro de movimientos | AC1: Una fila = una transacción
B2: Inicio | C2: ● Registro | D2: Dashboard | E2: Alimentación | F2: Hormiga | G2: Recurrentes | H2: Presupuestos | J2: Cuentas | K2: Categorías | L2: Config
B3: =HYPERLINK("#'Registro'!B"&IFERROR(MATCH(TRUE,INDEX(rFecha="",0),0)+5,5005),"＋ Nuevo movimiento") | D3: Atajos: Ctrl+; = fecha de hoy · Alt+↓ = abrir lista · Tab = siguiente campo · Solo Fecha y Monto son obligatorios: si dejas Tipo vacío se asume «Gasto». | J3: ="Movimientos: "&COUNTIF(rTipoE,"?*") | K3: ="Advertencias: "&COUNTIF(rEstado,"⚠*") | L3: =IF(COUNTIF(rObs,"DEMOSTRACIÓN")>0,"Filas DEMO: "&COUNTIF(rObs,"DEMOSTRACIÓN"),"")
B4: TUS DATOS · llena estas columnas | O4: CÁLCULOS AUTOMÁTICOS · no editar (pulsa «+» arriba de la columna P para ver el detalle)
B5: Fecha | C5: Tipo | D5: Categoría | E5: Subcategoría | F5: Descripción | G5: Monto | H5: Moneda | I5: Tasa USD | J5: Cuenta / método | K5: Cuenta destino | L5: Comercio | M5: Fijo/Variable | N5: Observaciones | O5: Estado | P5: Tipo efectivo | Q5: Cuenta efectiva | R5: Tasa aplicada | S5: Monto DOP | T5: Monto USD | U5: Gasto real DOP | V5: Ingreso DOP | W5: Resultado trading DOP | X5: Clasificación efectiva | Y5: Grupo alimentación | Z5: Día semana | AA5: Es hormiga | AB5: Cuenta saldo origen | AC5: Cuenta saldo destino | AD5: Tipo cta origen | AE5: Tipo cta destino | AF5: Efecto saldo origen | AG5: Efecto saldo destino | AH5: Flujo líquido DOP | AI5: Índice comercio
B6: 46235 | C6: Gasto | D6: Alimentación | E6: Cenas compradas | F6: DEMO · Cena comprada | G6: 600 | H6: DOP | J6: Tarjeta de crédito | L6: Pica pollo de la esquina | N6: DEMOSTRACIÓN | O6: =IF(AND(B6="",G6="",C6="",D6="",J6=""),"",IF(B6="","⚠ Falta fecha",IF(G6="","⚠ Falta monto",IF(Q6="","⚠ Falta cuenta",IF(ISNA(MATCH(Q6,ctaNombre,0)),"⚠ Cuenta no registrada",IF(AND(OR(P6="Gasto",P6="Reembolso"),D6=""),"⚠ Falta categoría",IF(AND(D6<>"",E6<>"",ISNA(MATCH(D6&"|"&E6,catClave,0))),"⚠ Subcategoría no corresponde",IF(AND(OR(P6="Transferencia",P6="Pago tarjeta"),K6=""),"⚠ Falta cuenta destino",IF(AND(K6<>"",P6<>"Transferencia",P6<>"Pago tarjeta"),"⚠ Destino solo aplica a transferencias",IF(AND(K6<>"",K6=Q6),"⚠ Origen igual a destino",IF(AND(K6<>"",ISNA(MATCH(K6,ctaNombre,0))),"⚠ Destino no registrado",IF(AND(P6="Pago tarjeta",AE6<>"Tarjeta de crédito"),"⚠ El destino debe ser tarjeta de crédito",IF(AND(P6="Gasto",E6="Depósitos y retiros"),"⚠ Usa tipo Transferencia",IF(AND(P6="Resultado trading",AD6<>"Cuenta de trading"),"⚠ Usa una cuenta de trading",IF(AND(G6<=0,P6<>"Ajuste",P6<>"Resultado trading"),"⚠ El monto debe ser positivo","✓"))))))))))))))) | P6: =IF(OR(B6="",G6=""),"",IF(C6="","Gasto",C6)) | Q6: =IF(P6="","",IF(J6<>"",J6,CuentaPred&"")) | R6: =IF(P6="","",IF(ISNUMBER(I6),I6,TasaUSD)) | S6: =IF(P6="","",IF(H6="USD",G6*R6,G6)) | T6: =IF(P6="","",IF(H6="USD",G6,IF(R6>0,G6/R6,0))) | U6: =IF(P6="","",IF(P6="Gasto",S6,IF(P6="Reembolso",-S6,0))) | V6: =IF(P6="","",IF(P6="Ingreso",S6,0)) | W6: =IF(P6="","",IF(P6="Resultado trading",S6,0)) | X6: =IF(OR(P6="Gasto",P6="Reembolso"),IF(M6<>"",M6,IFERROR(INDEX(catClasif,MATCH(D6&"|"&E6,catClave,0))&"","Variable")),"") | Y6: =IF(P6="","",IFERROR(INDEX(catGrupo,MATCH(D6&"|"&E6,catClave,0))&"","")) | Z6: =IF(P6="","",WEEKDAY(B6,2)) | AA6: =IF(P6="","",IF(AND(P6="Gasto",X6="Variable",D6<>catTrading,S6>0,S6<=Umbral),1,0)) | AB6: =IF(OR(P6="",Q6=""),"",IFERROR(IF(INDEX(ctaVinc,MATCH(Q6,ctaNombre,0))&""<>"",INDEX(ctaVinc,MATCH(Q6,ctaNombre,0))&"",Q6),Q6)) | AC6: =IF(OR(K6="",AND(P6<>"Transferencia",P6<>"Pago tarjeta")),"",IFERROR(IF(INDEX(ctaVinc,MATCH(K6,ctaNombre,0))&""<>"",INDEX(ctaVinc,MATCH(K6,ctaNombre,0))&"",K6),K6)) | AD6: =IF(AB6="","",IFERROR(INDEX(ctaTipo,MATCH(AB6,ctaNombre,0))&"","")) | AE6: =IF(AC6="","",IFERROR(INDEX(ctaTipo,MATCH(AC6,ctaNombre,0))&"","")) | AF6: =IF(OR(P6="",AB6=""),"",IF(OR(P6="Gasto",P6="Transferencia",P6="Pago tarjeta"),-1,1)*IF(IFERROR(INDEX(ctaMoneda,MATCH(AB6,ctaNombre,0))&"","DOP")="USD",T6,S6)) | AG6: =IF(AC6="","",IF(IFERROR(INDEX(ctaMoneda,MATCH(AC6,ctaNombre,0))&"","DOP")="USD",T6,S6)) | AH6: =IF(P6="","",IF(AND(AD6<>"",COUNTIFS(tcTipo,AD6,tcLiq,"Sí")>0),IF(OR(P6="Gasto",P6="Transferencia",P6="Pago tarjeta"),-1,1)*S6,0)+IF(AND(AE6<>"",COUNTIFS(tcTipo,AE6,tcLiq,"Sí")>0),S6,0)) | AI6: =IF(OR(L6="",P6=""),"",IF(COUNTIFS(L$6:L6,L6,P$6:P6,"?*")=1,MAX(AI$5:AI5)+1,""))
B7: 46235 | C7: Transferencia | F7: DEMO · Retiro en cajero | G7: 5000 | H7: DOP | J7: Banco principal | K7: Efectivo | N7: DEMOSTRACIÓN | O7: =IF(AND(B7="",G7="",C7="",D7="",J7=""),"",IF(B7="","⚠ Falta fecha",IF(G7="","⚠ Falta monto",IF(Q7="","⚠ Falta cuenta",IF(ISNA(MATCH(Q7,ctaNombre,0)),"⚠ Cuenta no registrada",IF(AND(OR(P7="Gasto",P7="Reembolso"),D7=""),"⚠ Falta categoría",IF(AND(D7<>"",E7<>"",ISNA(MATCH(D7&"|"&E7,catClave,0))),"⚠ Subcategoría no corresponde",IF(AND(OR(P7="Transferencia",P7="Pago tarjeta"),K7=""),"⚠ Falta cuenta destino",IF(AND(K7<>"",P7<>"Transferencia",P7<>"Pago tarjeta"),"⚠ Destino solo aplica a transferencias",IF(AND(K7<>"",K7=Q7),"⚠ Origen igual a destino",IF(AND(K7<>"",ISNA(MATCH(K7,ctaNombre,0))),"⚠ Destino no registrado",IF(AND(P7="Pago tarjeta",AE7<>"Tarjeta de crédito"),"⚠ El destino debe ser tarjeta de crédito",IF(AND(P7="Gasto",E7="Depósitos y retiros"),"⚠ Usa tipo Transferencia",IF(AND(P7="Resultado trading",AD7<>"Cuenta de trading"),"⚠ Usa una cuenta de trading",IF(AND(G7<=0,P7<>"Ajuste",P7<>"Resultado trading"),"⚠ El monto debe ser positivo","✓"))))))))))))))) | P7: =IF(OR(B7="",G7=""),"",IF(C7="","Gasto",C7)) | Q7: =IF(P7="","",IF(J7<>"",J7,CuentaPred&"")) | R7: =IF(P7="","",IF(ISNUMBER(I7),I7,TasaUSD)) | S7: =IF(P7="","",IF(H7="USD",G7*R7,G7)) | T7: =IF(P7="","",IF(H7="USD",G7,IF(R7>0,G7/R7,0))) | U7: =IF(P7="","",IF(P7="Gasto",S7,IF(P7="Reembolso",-S7,0))) | V7: =IF(P7="","",IF(P7="Ingreso",S7,0)) | W7: =IF(P7="","",IF(P7="Resultado trading",S7,0)) | X7: =IF(OR(P7="Gasto",P7="Reembolso"),IF(M7<>"",M7,IFERROR(INDEX(catClasif,MATCH(D7&"|"&E7,catClave,0))&"","Variable")),"") | Y7: =IF(P7="","",IFERROR(INDEX(catGrupo,MATCH(D7&"|"&E7,catClave,0))&"","")) | Z7: =IF(P7="","",WEEKDAY(B7,2)) | AA7: =IF(P7="","",IF(AND(P7="Gasto",X7="Variable",D7<>catTrading,S7>0,S7<=Umbral),1,0)) | AB7: =IF(OR(P7="",Q7=""),"",IFERROR(IF(INDEX(ctaVinc,MATCH(Q7,ctaNombre,0))&""<>"",INDEX(ctaVinc,MATCH(Q7,ctaNombre,0))&"",Q7),Q7)) | AC7: =IF(OR(K7="",AND(P7<>"Transferencia",P7<>"Pago tarjeta")),"",IFERROR(IF(INDEX(ctaVinc,MATCH(K7,ctaNombre,0))&""<>"",INDEX(ctaVinc,MATCH(K7,ctaNombre,0))&"",K7),K7)) | AD7: =IF(AB7="","",IFERROR(INDEX(ctaTipo,MATCH(AB7,ctaNombre,0))&"","")) | AE7: =IF(AC7="","",IFERROR(INDEX(ctaTipo,MATCH(AC7,ctaNombre,0))&"","")) | AF7: =IF(OR(P7="",AB7=""),"",IF(OR(P7="Gasto",P7="Transferencia",P7="Pago tarjeta"),-1,1)*IF(IFERROR(INDEX(ctaMoneda,MATCH(AB7,ctaNombre,0))&"","DOP")="USD",T7,S7)) | AG7: =IF(AC7="","",IF(IFERROR(INDEX(ctaMoneda,MATCH(AC7,ctaNombre,0))&"","DOP")="USD",T7,S7)) | AH7: =IF(P7="","",IF(AND(AD7<>"",COUNTIFS(tcTipo,AD7,tcLiq,"Sí")>0),IF(OR(P7="Gasto",P7="Transferencia",P7="Pago tarjeta"),-1,1)*S7,0)+IF(AND(AE7<>"",COUNTIFS(tcTipo,AE7,tcLiq,"Sí")>0),S7,0)) | AI7: =IF(OR(L7="",P7=""),"",IF(COUNTIFS(L$6:L7,L7,P$6:P7,"?*")=1,MAX(AI$5:AI6)+1,""))
B8: 46236 | C8: Gasto | D8: Alimentación | E8: Supermercado | F8: DEMO · Compra de supermercado | G8: 5850 | H8: DOP | J8: Tarjeta de crédito | L8: Supermercado principal | N8: DEMOSTRACIÓN | O8: =IF(AND(B8="",G8="",C8="",D8="",J8=""),"",IF(B8="","⚠ Falta fecha",IF(G8="","⚠ Falta monto",IF(Q8="","⚠ Falta cuenta",IF(ISNA(MATCH(Q8,ctaNombre,0)),"⚠ Cuenta no registrada",IF(AND(OR(P8="Gasto",P8="Reembolso"),D8=""),"⚠ Falta categoría",IF(AND(D8<>"",E8<>"",ISNA(MATCH(D8&"|"&E8,catClave,0))),"⚠ Subcategoría no corresponde",IF(AND(OR(P8="Transferencia",P8="Pago tarjeta"),K8=""),"⚠ Falta cuenta destino",IF(AND(K8<>"",P8<>"Transferencia",P8<>"Pago tarjeta"),"⚠ Destino solo aplica a transferencias",IF(AND(K8<>"",K8=Q8),"⚠ Origen igual a destino",IF(AND(K8<>"",ISNA(MATCH(K8,ctaNombre,0))),"⚠ Destino no registrado",IF(AND(P8="Pago tarjeta",AE8<>"Tarjeta de crédito"),"⚠ El destino debe ser tarjeta de crédito",IF(AND(P8="Gasto",E8="Depósitos y retiros"),"⚠ Usa tipo Transferencia",IF(AND(P8="Resultado trading",AD8<>"Cuenta de trading"),"⚠ Usa una cuenta de trading",IF(AND(G8<=0,P8<>"Ajuste",P8<>"Resultado trading"),"⚠ El monto debe ser positivo","✓"))))))))))))))) | P8: =IF(OR(B8="",G8=""),"",IF(C8="","Gasto",C8)) | Q8: =IF(P8="","",IF(J8<>"",J8,CuentaPred&"")) | R8: =IF(P8="","",IF(ISNUMBER(I8),I8,TasaUSD)) | S8: =IF(P8="","",IF(H8="USD",G8*R8,G8)) | T8: =IF(P8="","",IF(H8="USD",G8,IF(R8>0,G8/R8,0))) | U8: =IF(P8="","",IF(P8="Gasto",S8,IF(P8="Reembolso",-S8,0))) | V8: =IF(P8="","",IF(P8="Ingreso",S8,0)) | W8: =IF(P8="","",IF(P8="Resultado trading",S8,0)) | X8: =IF(OR(P8="Gasto",P8="Reembolso"),IF(M8<>"",M8,IFERROR(INDEX(catClasif,MATCH(D8&"|"&E8,catClave,0))&"","Variable")),"") | Y8: =IF(P8="","",IFERROR(INDEX(catGrupo,MATCH(D8&"|"&E8,catClave,0))&"","")) | Z8: =IF(P8="","",WEEKDAY(B8,2)) | AA8: =IF(P8="","",IF(AND(P8="Gasto",X8="Variable",D8<>catTrading,S8>0,S8<=Umbral),1,0)) | AB8: =IF(OR(P8="",Q8=""),"",IFERROR(IF(INDEX(ctaVinc,MATCH(Q8,ctaNombre,0))&""<>"",INDEX(ctaVinc,MATCH(Q8,ctaNombre,0))&"",Q8),Q8)) | AC8: =IF(OR(K8="",AND(P8<>"Transferencia",P8<>"Pago tarjeta")),"",IFERROR(IF(INDEX(ctaVinc,MATCH(K8,ctaNombre,0))&""<>"",INDEX(ctaVinc,MATCH(K8,ctaNombre,0))&"",K8),K8)) | AD8: =IF(AB8="","",IFERROR(INDEX(ctaTipo,MATCH(AB8,ctaNombre,0))&"","")) | AE8: =IF(AC8="","",IFERROR(INDEX(ctaTipo,MATCH(AC8,ctaNombre,0))&"","")) | AF8: =IF(OR(P8="",AB8=""),"",IF(OR(P8="Gasto",P8="Transferencia",P8="Pago tarjeta"),-1,1)*IF(IFERROR(INDEX(ctaMoneda,MATCH(AB8,ctaNombre,0))&"","DOP")="USD",T8,S8)) | AG8: =IF(AC8="","",IF(IFERROR(INDEX(ctaMoneda,MATCH(AC8,ctaNombre,0))&"","DOP")="USD",T8,S8)) | AH8: =IF(P8="","",IF(AND(AD8<>"",COUNTIFS(tcTipo,AD8,tcLiq,"Sí")>0),IF(OR(P8="Gasto",P8="Transferencia",P8="Pago tarjeta"),-1,1)*S8,0)+IF(AND(AE8<>"",COUNTIFS(tcTipo,AE8,tcLiq,"Sí")>0),S8,0)) | AI8: =IF(OR(L8="",P8=""),"",IF(COUNTIFS(L$6:L8,L8,P$6:P8,"?*")=1,MAX(AI$5:AI7)+1,""))
B9: 46237 | C9: Gasto | D9: Transporte y vehículo | E9: Combustible | F9: DEMO · Combustible | G9: 2900 | H9: DOP | J9: Tarjeta de crédito | L9: Estación de combustible | N9: DEMOSTRACIÓN | O9: =IF(AND(B9="",G9="",C9="",D9="",J9=""),"",IF(B9="","⚠ Falta fecha",IF(G9="","⚠ Falta monto",IF(Q9="","⚠ Falta cuenta",IF(ISNA(MATCH(Q9,ctaNombre,0)),"⚠ Cuenta no registrada",IF(AND(OR(P9="Gasto",P9="Reembolso"),D9=""),"⚠ Falta categoría",IF(AND(D9<>"",E9<>"",ISNA(MATCH(D9&"|"&E9,catClave,0))),"⚠ Subcategoría no corresponde",IF(AND(OR(P9="Transferencia",P9="Pago tarjeta"),K9=""),"⚠ Falta cuenta destino",IF(AND(K9<>"",P9<>"Transferencia",P9<>"Pago tarjeta"),"⚠ Destino solo aplica a transferencias",IF(AND(K9<>"",K9=Q9),"⚠ Origen igual a destino",IF(AND(K9<>"",ISNA(MATCH(K9,ctaNombre,0))),"⚠ Destino no registrado",IF(AND(P9="Pago tarjeta",AE9<>"Tarjeta de crédito"),"⚠ El destino debe ser tarjeta de crédito",IF(AND(P9="Gasto",E9="Depósitos y retiros"),"⚠ Usa tipo Transferencia",IF(AND(P9="Resultado trading",AD9<>"Cuenta de trading"),"⚠ Usa una cuenta de trading",IF(AND(G9<=0,P9<>"Ajuste",P9<>"Resultado trading"),"⚠ El monto debe ser positivo","✓"))))))))))))))) | P9: =IF(OR(B9="",G9=""),"",IF(C9="","Gasto",C9)) | Q9: =IF(P9="","",IF(J9<>"",J9,CuentaPred&"")) | R9: =IF(P9="","",IF(ISNUMBER(I9),I9,TasaUSD)) | S9: =IF(P9="","",IF(H9="USD",G9*R9,G9)) | T9: =IF(P9="","",IF(H9="USD",G9,IF(R9>0,G9/R9,0))) | U9: =IF(P9="","",IF(P9="Gasto",S9,IF(P9="Reembolso",-S9,0))) | V9: =IF(P9="","",IF(P9="Ingreso",S9,0)) | W9: =IF(P9="","",IF(P9="Resultado trading",S9,0)) | X9: =IF(OR(P9="Gasto",P9="Reembolso"),IF(M9<>"",M9,IFERROR(INDEX(catClasif,MATCH(D9&"|"&E9,catClave,0))&"","Variable")),"") | Y9: =IF(P9="","",IFERROR(INDEX(catGrupo,MATCH(D9&"|"&E9,catClave,0))&"","")) | Z9: =IF(P9="","",WEEKDAY(B9,2)) | AA9: =IF(P9="","",IF(AND(P9="Gasto",X9="Variable",D9<>catTrading,S9>0,S9<=Umbral),1,0)) | AB9: =IF(OR(P9="",Q9=""),"",IFERROR(IF(INDEX(ctaVinc,MATCH(Q9,ctaNombre,0))&""<>"",INDEX(ctaVinc,MATCH(Q9,ctaNombre,0))&"",Q9),Q9)) | AC9: =IF(OR(K9="",AND(P9<>"Transferencia",P9<>"Pago tarjeta")),"",IFERROR(IF(INDEX(ctaVinc,MATCH(K9,ctaNombre,0))&""<>"",INDEX(ctaVinc,MATCH(K9,ctaNombre,0))&"",K9),K9)) | AD9: =IF(AB9="","",IFERROR(INDEX(ctaTipo,MATCH(AB9,ctaNombre,0))&"","")) | AE9: =IF(AC9="","",IFERROR(INDEX(ctaTipo,MATCH(AC9,ctaNombre,0))&"","")) | AF9: =IF(OR(P9="",AB9=""),"",IF(OR(P9="Gasto",P9="Transferencia",P9="Pago tarjeta"),-1,1)*IF(IFERROR(INDEX(ctaMoneda,MATCH(AB9,ctaNombre,0))&"","DOP")="USD",T9,S9)) | AG9: =IF(AC9="","",IF(IFERROR(INDEX(ctaMoneda,MATCH(AC9,ctaNombre,0))&"","DOP")="USD",T9,S9)) | AH9: =IF(P9="","",IF(AND(AD9<>"",COUNTIFS(tcTipo,AD9,tcLiq,"Sí")>0),IF(OR(P9="Gasto",P9="Transferencia",P9="Pago tarjeta"),-1,1)*S9,0)+IF(AND(AE9<>"",COUNTIFS(tcTipo,AE9,tcLiq,"Sí")>0),S9,0)) | AI9: =IF(OR(L9="",P9=""),"",IF(COUNTIFS(L$6:L9,L9,P$6:P9,"?*")=1,MAX(AI$5:AI8)+1,""))
B10: 46237 | C10: Gasto | D10: Tecnología y suscripciones | E10: Herramientas de inteligencia artificial | F10: DEMO · Suscripción herramienta IA | G10: 20 | H10: USD | J10: Tarjeta de crédito | L10: Herramienta IA | N10: DEMOSTRACIÓN | O10: =IF(AND(B10="",G10="",C10="",D10="",J10=""),"",IF(B10="","⚠ Falta fecha",IF(G10="","⚠ Falta monto",IF(Q10="","⚠ Falta cuenta",IF(ISNA(MATCH(Q10,ctaNombre,0)),"⚠ Cuenta no registrada",IF(AND(OR(P10="Gasto",P10="Reembolso"),D10=""),"⚠ Falta categoría",IF(AND(D10<>"",E10<>"",ISNA(MATCH(D10&"|"&E10,catClave,0))),"⚠ Subcategoría no corresponde",IF(AND(OR(P10="Transferencia",P10="Pago tarjeta"),K10=""),"⚠ Falta cuenta destino",IF(AND(K10<>"",P10<>"Transferencia",P10<>"Pago tarjeta"),"⚠ Destino solo aplica a transferencias",IF(AND(K10<>"",K10=Q10),"⚠ Origen igual a destino",IF(AND(K10<>"",ISNA(MATCH(K10,ctaNombre,0))),"⚠ Destino no registrado",IF(AND(P10="Pago tarjeta",AE10<>"Tarjeta de crédito"),"⚠ El destino debe ser tarjeta de crédito",IF(AND(P10="Gasto",E10="Depósitos y retiros"),"⚠ Usa tipo Transferencia",IF(AND(P10="Resultado trading",AD10<>"Cuenta de trading"),"⚠ Usa una cuenta de trading",IF(AND(G10<=0,P10<>"Ajuste",P10<>"Resultado trading"),"⚠ El monto debe ser positivo","✓"))))))))))))))) | P10: =IF(OR(B10="",G10=""),"",IF(C10="","Gasto",C10)) | Q10: =IF(P10="","",IF(J10<>"",J10,CuentaPred&"")) | R10: =IF(P10="","",IF(ISNUMBER(I10),I10,TasaUSD)) | S10: =IF(P10="","",IF(H10="USD",G10*R10,G10)) | T10: =IF(P10="","",IF(H10="USD",G10,IF(R10>0,G10/R10,0))) | U10: =IF(P10="","",IF(P10="Gasto",S10,IF(P10="Reembolso",-S10,0))) | V10: =IF(P10="","",IF(P10="Ingreso",S10,0)) | W10: =IF(P10="","",IF(P10="Resultado trading",S10,0)) | X10: =IF(OR(P10="Gasto",P10="Reembolso"),IF(M10<>"",M10,IFERROR(INDEX(catClasif,MATCH(D10&"|"&E10,catClave,0))&"","Variable")),"") | Y10: =IF(P10="","",IFERROR(INDEX(catGrupo,MATCH(D10&"|"&E10,catClave,0))&"","")) | Z10: =IF(P10="","",WEEKDAY(B10,2)) | AA10: =IF(P10="","",IF(AND(P10="Gasto",X10="Variable",D10<>catTrading,S10>0,S10<=Umbral),1,0)) | AB10: =IF(OR(P10="",Q10=""),"",IFERROR(IF(INDEX(ctaVinc,MATCH(Q10,ctaNombre,0))&""<>"",INDEX(ctaVinc,MATCH(Q10,ctaNombre,0))&"",Q10),Q10)) | AC10: =IF(OR(K10="",AND(P10<>"Transferencia",P10<>"Pago tarjeta")),"",IFERROR(IF(INDEX(ctaVinc,MATCH(K10,ctaNombre,0))&""<>"",INDEX(ctaVinc,MATCH(K10,ctaNombre,0))&"",K10),K10)) | AD10: =IF(AB10="","",IFERROR(INDEX(ctaTipo,MATCH(AB10,ctaNombre,0))&"","")) | AE10: =IF(AC10="","",IFERROR(INDEX(ctaTipo,MATCH(AC10,ctaNombre,0))&"","")) | AF10: =IF(OR(P10="",AB10=""),"",IF(OR(P10="Gasto",P10="Transferencia",P10="Pago tarjeta"),-1,1)*IF(IFERROR(INDEX(ctaMoneda,MATCH(AB10,ctaNombre,0))&"","DOP")="USD",T10,S10)) | AG10: =IF(AC10="","",IF(IFERROR(INDEX(ctaMoneda,MATCH(AC10,ctaNombre,0))&"","DOP")="USD",T10,S10)) | AH10: =IF(P10="","",IF(AND(AD10<>"",COUNTIFS(tcTipo,AD10,tcLiq,"Sí")>0),IF(OR(P10="Gasto",P10="Transferencia",P10="Pago tarjeta"),-1,1)*S10,0)+IF(AND(AE10<>"",COUNTIFS(tcTipo,AE10,tcLiq,"Sí")>0),S10,0)) | AI10: =IF(OR(L10="",P10=""),"",IF(COUNTIFS(L$6:L10,L10,P$6:P10,"?*")=1,MAX(AI$5:AI9)+1,""))
B11: 46238 | C11: Gasto | D11: Alimentación | E11: Almuerzos laborales | F11: DEMO · Almuerzo laboral | G11: 375 | H11: DOP | J11: Tarjeta de débito | L11: Comedor ejecutivo | N11: DEMOSTRACIÓN | O11: =IF(AND(B11="",G11="",C11="",D11="",J11=""),"",IF(B11="","⚠ Falta fecha",IF(G11="","⚠ Falta monto",IF(Q11="","⚠ Falta cuenta",IF(ISNA(MATCH(Q11,ctaNombre,0)),"⚠ Cuenta no registrada",IF(AND(OR(P11="Gasto",P11="Reembolso"),D11=""),"⚠ Falta categoría",IF(AND(D11<>"",E11<>"",ISNA(MATCH(D11&"|"&E11,catClave,0))),"⚠ Subcategoría no corresponde",IF(AND(OR(P11="Transferencia",P11="Pago tarjeta"),K11=""),"⚠ Falta cuenta destino",IF(AND(K11<>"",P11<>"Transferencia",P11<>"Pago tarjeta"),"⚠ Destino solo aplica a transferencias",IF(AND(K11<>"",K11=Q11),"⚠ Origen igual a destino",IF(AND(K11<>"",ISNA(MATCH(K11,ctaNombre,0))),"⚠ Destino no registrado",IF(AND(P11="Pago tarjeta",AE11<>"Tarjeta de crédito"),"⚠ El destino debe ser tarjeta de crédito",IF(AND(P11="Gasto",E11="Depósitos y retiros"),"⚠ Usa tipo Transferencia",IF(AND(P11="Resultado trading",AD11<>"Cuenta de trading"),"⚠ Usa una cuenta de trading",IF(AND(G11<=0,P11<>"Ajuste",P11<>"Resultado trading"),"⚠ El monto debe ser positivo","✓"))))))))))))))) | P11: =IF(OR(B11="",G11=""),"",IF(C11="","Gasto",C11)) | Q11: =IF(P11="","",IF(J11<>"",J11,CuentaPred&"")) | R11: =IF(P11="","",IF(ISNUMBER(I11),I11,TasaUSD)) | S11: =IF(P11="","",IF(H11="USD",G11*R11,G11)) | T11: =IF(P11="","",IF(H11="USD",G11,IF(R11>0,G11/R11,0))) | U11: =IF(P11="","",IF(P11="Gasto",S11,IF(P11="Reembolso",-S11,0))) | V11: =IF(P11="","",IF(P11="Ingreso",S11,0)) | W11: =IF(P11="","",IF(P11="Resultado trading",S11,0)) | X11: =IF(OR(P11="Gasto",P11="Reembolso"),IF(M11<>"",M11,IFERROR(INDEX(catClasif,MATCH(D11&"|"&E11,catClave,0))&"","Variable")),"") | Y11: =IF(P11="","",IFERROR(INDEX(catGrupo,MATCH(D11&"|"&E11,catClave,0))&"","")) | Z11: =IF(P11="","",WEEKDAY(B11,2)) | AA11: =IF(P11="","",IF(AND(P11="Gasto",X11="Variable",D11<>catTrading,S11>0,S11<=Umbral),1,0)) | AB11: =IF(OR(P11="",Q11=""),"",IFERROR(IF(INDEX(ctaVinc,MATCH(Q11,ctaNombre,0))&""<>"",INDEX(ctaVinc,MATCH(Q11,ctaNombre,0))&"",Q11),Q11)) | AC11: =IF(OR(K11="",AND(P11<>"Transferencia",P11<>"Pago tarjeta")),"",IFERROR(IF(INDEX(ctaVinc,MATCH(K11,ctaNombre,0))&""<>"",INDEX(ctaVinc,MATCH(K11,ctaNombre,0))&"",K11),K11)) | AD11: =IF(AB11="","",IFERROR(INDEX(ctaTipo,MATCH(AB11,ctaNombre,0))&"","")) | AE11: =IF(AC11="","",IFERROR(INDEX(ctaTipo,MATCH(AC11,ctaNombre,0))&"","")) | AF11: =IF(OR(P11="",AB11=""),"",IF(OR(P11="Gasto",P11="Transferencia",P11="Pago tarjeta"),-1,1)*IF(IFERROR(INDEX(ctaMoneda,MATCH(AB11,ctaNombre,0))&"","DOP")="USD",T11,S11)) | AG11: =IF(AC11="","",IF(IFERROR(INDEX(ctaMoneda,MATCH(AC11,ctaNombre,0))&"","DOP")="USD",T11,S11)) | AH11: =IF(P11="","",IF(AND(AD11<>"",COUNTIFS(tcTipo,AD11,tcLiq,"Sí")>0),IF(OR(P11="Gasto",P11="Transferencia",P11="Pago tarjeta"),-1,1)*S11,0)+IF(AND(AE11<>"",COUNTIFS(tcTipo,AE11,tcLiq,"Sí")>0),S11,0)) | AI11: =IF(OR(L11="",P11=""),"",IF(COUNTIFS(L$6:L11,L11,P$6:P11,"?*")=1,MAX(AI$5:AI10)+1,""))
B12: 46238 | C12: Gasto | D12: Alimentación | E12: Bebidas, snacks y otros consumos | F12: DEMO · Café | G12: 160 | H12: DOP | J12: Efectivo | L12: Colmado del barrio | N12: DEMOSTRACIÓN | O12: =IF(AND(B12="",G12="",C12="",D12="",J12=""),"",IF(B12="","⚠ Falta fecha",IF(G12="","⚠ Falta monto",IF(Q12="","⚠ Falta cuenta",IF(ISNA(MATCH(Q12,ctaNombre,0)),"⚠ Cuenta no registrada",IF(AND(OR(P12="Gasto",P12="Reembolso"),D12=""),"⚠ Falta categoría",IF(AND(D12<>"",E12<>"",ISNA(MATCH(D12&"|"&E12,catClave,0))),"⚠ Subcategoría no corresponde",IF(AND(OR(P12="Transferencia",P12="Pago tarjeta"),K12=""),"⚠ Falta cuenta destino",IF(AND(K12<>"",P12<>"Transferencia",P12<>"Pago tarjeta"),"⚠ Destino solo aplica a transferencias",IF(AND(K12<>"",K12=Q12),"⚠ Origen igual a destino",IF(AND(K12<>"",ISNA(MATCH(K12,ctaNombre,0))),"⚠ Destino no registrado",IF(AND(P12="Pago tarjeta",AE12<>"Tarjeta de crédito"),"⚠ El destino debe ser tarjeta de crédito",IF(AND(P12="Gasto",E12="Depósitos y retiros"),"⚠ Usa tipo Transferencia",IF(AND(P12="Resultado trading",AD12<>"Cuenta de trading"),"⚠ Usa una cuenta de trading",IF(AND(G12<=0,P12<>"Ajuste",P12<>"Resultado trading"),"⚠ El monto debe ser positivo","✓"))))))))))))))) | P12: =IF(OR(B12="",G12=""),"",IF(C12="","Gasto",C12)) | Q12: =IF(P12="","",IF(J12<>"",J12,CuentaPred&"")) | R12: =IF(P12="","",IF(ISNUMBER(I12),I12,TasaUSD)) | S12: =IF(P12="","",IF(H12="USD",G12*R12,G12)) | T12: =IF(P12="","",IF(H12="USD",G12,IF(R12>0,G12/R12,0))) | U12: =IF(P12="","",IF(P12="Gasto",S12,IF(P12="Reembolso",-S12,0))) | V12: =IF(P12="","",IF(P12="Ingreso",S12,0)) | W12: =IF(P12="","",IF(P12="Resultado trading",S12,0)) | X12: =IF(OR(P12="Gasto",P12="Reembolso"),IF(M12<>"",M12,IFERROR(INDEX(catClasif,MATCH(D12&"|"&E12,catClave,0))&"","Variable")),"") | Y12: =IF(P12="","",IFERROR(INDEX(catGrupo,MATCH(D12&"|"&E12,catClave,0))&"","")) | Z12: =IF(P12="","",WEEKDAY(B12,2)) | AA12: =IF(P12="","",IF(AND(P12="Gasto",X12="Variable",D12<>catTrading,S12>0,S12<=Umbral),1,0)) | AB12: =IF(OR(P12="",Q12=""),"",IFERROR(IF(INDEX(ctaVinc,MATCH(Q12,ctaNombre,0))&""<>"",INDEX(ctaVinc,MATCH(Q12,ctaNombre,0))&"",Q12),Q12)) | AC12: =IF(OR(K12="",AND(P12<>"Transferencia",P12<>"Pago tarjeta")),"",IFERROR(IF(INDEX(ctaVinc,MATCH(K12,ctaNombre,0))&""<>"",INDEX(ctaVinc,MATCH(K12,ctaNombre,0))&"",K12),K12)) | AD12: =IF(AB12="","",IFERROR(INDEX(ctaTipo,MATCH(AB12,ctaNombre,0))&"","")) | AE12: =IF(AC12="","",IFERROR(INDEX(ctaTipo,MATCH(AC12,ctaNombre,0))&"","")) | AF12: =IF(OR(P12="",AB12=""),"",IF(OR(P12="Gasto",P12="Transferencia",P12="Pago tarjeta"),-1,1)*IF(IFERROR(INDEX(ctaMoneda,MATCH(AB12,ctaNombre,0))&"","DOP")="USD",T12,S12)) | AG12: =IF(AC12="","",IF(IFERROR(INDEX(ctaMoneda,MATCH(AC12,ctaNombre,0))&"","DOP")="USD",T12,S12)) | AH12: =IF(P12="","",IF(AND(AD12<>"",COUNTIFS(tcTipo,AD12,tcLiq,"Sí")>0),IF(OR(P12="Gasto",P12="Transferencia",P12="Pago tarjeta"),-1,1)*S12,0)+IF(AND(AE12<>"",COUNTIFS(tcTipo,AE12,tcLiq,"Sí")>0),S12,0)) | AI12: =IF(OR(L12="",P12=""),"",IF(COUNTIFS(L$6:L12,L12,P$6:P12,"?*")=1,MAX(AI$5:AI11)+1,""))
B13: 46239 | C13: Gasto | D13: Alimentación | E13: Desayunos comprados | F13: DEMO · Desayuno en la oficina | G13: 290 | H13: DOP | J13: Efectivo | L13: Cafetería del trabajo | N13: DEMOSTRACIÓN | O13: =IF(AND(B13="",G13="",C13="",D13="",J13=""),"",IF(B13="","⚠ Falta fecha",IF(G13="","⚠ Falta monto",IF(Q13="","⚠ Falta cuenta",IF(ISNA(MATCH(Q13,ctaNombre,0)),"⚠ Cuenta no registrada",IF(AND(OR(P13="Gasto",P13="Reembolso"),D13=""),"⚠ Falta categoría",IF(AND(D13<>"",E13<>"",ISNA(MATCH(D13&"|"&E13,catClave,0))),"⚠ Subcategoría no corresponde",IF(AND(OR(P13="Transferencia",P13="Pago tarjeta"),K13=""),"⚠ Falta cuenta destino",IF(AND(K13<>"",P13<>"Transferencia",P13<>"Pago tarjeta"),"⚠ Destino solo aplica a transferencias",IF(AND(K13<>"",K13=Q13),"⚠ Origen igual a destino",IF(AND(K13<>"",ISNA(MATCH(K13,ctaNombre,0))),"⚠ Destino no registrado",IF(AND(P13="Pago tarjeta",AE13<>"Tarjeta de crédito"),"⚠ El destino debe ser tarjeta de crédito",IF(AND(P13="Gasto",E13="Depósitos y retiros"),"⚠ Usa tipo Transferencia",IF(AND(P13="Resultado trading",AD13<>"Cuenta de trading"),"⚠ Usa una cuenta de trading",IF(AND(G13<=0,P13<>"Ajuste",P13<>"Resultado trading"),"⚠ El monto debe ser positivo","✓"))))))))))))))) | P13: =IF(OR(B13="",G13=""),"",IF(C13="","Gasto",C13)) | Q13: =IF(P13="","",IF(J13<>"",J13,CuentaPred&"")) | R13: =IF(P13="","",IF(ISNUMBER(I13),I13,TasaUSD)) | S13: =IF(P13="","",IF(H13="USD",G13*R13,G13)) | T13: =IF(P13="","",IF(H13="USD",G13,IF(R13>0,G13/R13,0))) | U13: =IF(P13="","",IF(P13="Gasto",S13,IF(P13="Reembolso",-S13,0))) | V13: =IF(P13="","",IF(P13="Ingreso",S13,0)) | W13: =IF(P13="","",IF(P13="Resultado trading",S13,0)) | X13: =IF(OR(P13="Gasto",P13="Reembolso"),IF(M13<>"",M13,IFERROR(INDEX(catClasif,MATCH(D13&"|"&E13,catClave,0))&"","Variable")),"") | Y13: =IF(P13="","",IFERROR(INDEX(catGrupo,MATCH(D13&"|"&E13,catClave,0))&"","")) | Z13: =IF(P13="","",WEEKDAY(B13,2)) | AA13: =IF(P13="","",IF(AND(P13="Gasto",X13="Variable",D13<>catTrading,S13>0,S13<=Umbral),1,0)) | AB13: =IF(OR(P13="",Q13=""),"",IFERROR(IF(INDEX(ctaVinc,MATCH(Q13,ctaNombre,0))&""<>"",INDEX(ctaVinc,MATCH(Q13,ctaNombre,0))&"",Q13),Q13)) | AC13: =IF(OR(K13="",AND(P13<>"Transferencia",P13<>"Pago tarjeta")),"",IFERROR(IF(INDEX(ctaVinc,MATCH(K13,ctaNombre,0))&""<>"",INDEX(ctaVinc,MATCH(K13,ctaNombre,0))&"",K13),K13)) | AD13: =IF(AB13="","",IFERROR(INDEX(ctaTipo,MATCH(AB13,ctaNombre,0))&"","")) | AE13: =IF(AC13="","",IFERROR(INDEX(ctaTipo,MATCH(AC13,ctaNombre,0))&"","")) | AF13: =IF(OR(P13="",AB13=""),"",IF(OR(P13="Gasto",P13="Transferencia",P13="Pago tarjeta"),-1,1)*IF(IFERROR(INDEX(ctaMoneda,MATCH(AB13,ctaNombre,0))&"","DOP")="USD",T13,S13)) | AG13: =IF(AC13="","",IF(IFERROR(INDEX(ctaMoneda,MATCH(AC13,ctaNombre,0))&"","DOP")="USD",T13,S13)) | AH13: =IF(P13="","",IF(AND(AD13<>"",COUNTIFS(tcTipo,AD13,tcLiq,"Sí")>0),IF(OR(P13="Gasto",P13="Transferencia",P13="Pago tarjeta"),-1,1)*S13,0)+IF(AND(AE13<>"",COUNTIFS(tcTipo,AE13,tcLiq,"Sí")>0),S13,0)) | AI13: =IF(OR(L13="",P13=""),"",IF(COUNTIFS(L$6:L13,L13,P$6:P13,"?*")=1,MAX(AI$5:AI12)+1,""))
B14: 46239 | C14: Gasto | D14: Alimentación | E14: Cenas compradas | F14: DEMO · Cena comprada | G14: 525 | H14: DOP | J14: Tarjeta de crédito | L14: Pizzería del sector | N14: DEMOSTRACIÓN | O14: =IF(AND(B14="",G14="",C14="",D14="",J14=""),"",IF(B14="","⚠ Falta fecha",IF(G14="","⚠ Falta monto",IF(Q14="","⚠ Falta cuenta",IF(ISNA(MATCH(Q14,ctaNombre,0)),"⚠ Cuenta no registrada",IF(AND(OR(P14="Gasto",P14="Reembolso"),D14=""),"⚠ Falta categoría",IF(AND(D14<>"",E14<>"",ISNA(MATCH(D14&"|"&E14,catClave,0))),"⚠ Subcategoría no corresponde",IF(AND(OR(P14="Transferencia",P14="Pago tarjeta"),K14=""),"⚠ Falta cuenta destino",IF(AND(K14<>"",P14<>"Transferencia",P14<>"Pago tarjeta"),"⚠ Destino solo aplica a transferencias",IF(AND(K14<>"",K14=Q14),"⚠ Origen igual a destino",IF(AND(K14<>"",ISNA(MATCH(K14,ctaNombre,0))),"⚠ Destino no registrado",IF(AND(P14="Pago tarjeta",AE14<>"Tarjeta de crédito"),"⚠ El destino debe ser tarjeta de crédito",IF(AND(P14="Gasto",E14="Depósitos y retiros"),"⚠ Usa tipo Transferencia",IF(AND(P14="Resultado trading",AD14<>"Cuenta de trading"),"⚠ Usa una cuenta de trading",IF(AND(G14<=0,P14<>"Ajuste",P14<>"Resultado trading"),"⚠ El monto debe ser positivo","✓"))))))))))))))) | P14: =IF(OR(B14="",G14=""),"",IF(C14="","Gasto",C14)) | Q14: =IF(P14="","",IF(J14<>"",J14,CuentaPred&"")) | R14: =IF(P14="","",IF(ISNUMBER(I14),I14,TasaUSD)) | S14: =IF(P14="","",IF(H14="USD",G14*R14,G14)) | T14: =IF(P14="","",IF(H14="USD",G14,IF(R14>0,G14/R14,0))) | U14: =IF(P14="","",IF(P14="Gasto",S14,IF(P14="Reembolso",-S14,0))) | V14: =IF(P14="","",IF(P14="Ingreso",S14,0)) | W14: =IF(P14="","",IF(P14="Resultado trading",S14,0)) | X14: =IF(OR(P14="Gasto",P14="Reembolso"),IF(M14<>"",M14,IFERROR(INDEX(catClasif,MATCH(D14&"|"&E14,catClave,0))&"","Variable")),"") | Y14: =IF(P14="","",IFERROR(INDEX(catGrupo,MATCH(D14&"|"&E14,catClave,0))&"","")) | Z14: =IF(P14="","",WEEKDAY(B14,2)) | AA14: =IF(P14="","",IF(AND(P14="Gasto",X14="Variable",D14<>catTrading,S14>0,S14<=Umbral),1,0)) | AB14: =IF(OR(P14="",Q14=""),"",IFERROR(IF(INDEX(ctaVinc,MATCH(Q14,ctaNombre,0))&""<>"",INDEX(ctaVinc,MATCH(Q14,ctaNombre,0))&"",Q14),Q14)) | AC14: =IF(OR(K14="",AND(P14<>"Transferencia",P14<>"Pago tarjeta")),"",IFERROR(IF(INDEX(ctaVinc,MATCH(K14,ctaNombre,0))&""<>"",INDEX(ctaVinc,MATCH(K14,ctaNombre,0))&"",K14),K14)) | AD14: =IF(AB14="","",IFERROR(INDEX(ctaTipo,MATCH(AB14,ctaNombre,0))&"","")) | AE14: =IF(AC14="","",IFERROR(INDEX(ctaTipo,MATCH(AC14,ctaNombre,0))&"","")) | AF14: =IF(OR(P14="",AB14=""),"",IF(OR(P14="Gasto",P14="Transferencia",P14="Pago tarjeta"),-1,1)*IF(IFERROR(INDEX(ctaMoneda,MATCH(AB14,ctaNombre,0))&"","DOP")="USD",T14,S14)) | AG14: =IF(AC14="","",IF(IFERROR(INDEX(ctaMoneda,MATCH(AC14,ctaNombre,0))&"","DOP")="USD",T14,S14)) | AH14: =IF(P14="","",IF(AND(AD14<>"",COUNTIFS(tcTipo,AD14,tcLiq,"Sí")>0),IF(OR(P14="Gasto",P14="Transferencia",P14="Pago tarjeta"),-1,1)*S14,0)+IF(AND(AE14<>"",COUNTIFS(tcTipo,AE14,tcLiq,"Sí")>0),S14,0)) | AI14: =IF(OR(L14="",P14=""),"",IF(COUNTIFS(L$6:L14,L14,P$6:P14,"?*")=1,MAX(AI$5:AI13)+1,""))
B15: 46239 | C15: Gasto | D15: Hogar y servicios | E15: Internet | F15: DEMO · Internet del hogar | G15: 2050 | H15: DOP | J15: Banco principal | L15: Proveedor de internet | N15: DEMOSTRACIÓN | O15: =IF(AND(B15="",G15="",C15="",D15="",J15=""),"",IF(B15="","⚠ Falta fecha",IF(G15="","⚠ Falta monto",IF(Q15="","⚠ Falta cuenta",IF(ISNA(MATCH(Q15,ctaNombre,0)),"⚠ Cuenta no registrada",IF(AND(OR(P15="Gasto",P15="Reembolso"),D15=""),"⚠ Falta categoría",IF(AND(D15<>"",E15<>"",ISNA(MATCH(D15&"|"&E15,catClave,0))),"⚠ Subcategoría no corresponde",IF(AND(OR(P15="Transferencia",P15="Pago tarjeta"),K15=""),"⚠ Falta cuenta destino",IF(AND(K15<>"",P15<>"Transferencia",P15<>"Pago tarjeta"),"⚠ Destino solo aplica a transferencias",IF(AND(K15<>"",K15=Q15),"⚠ Origen igual a destino",IF(AND(K15<>"",ISNA(MATCH(K15,ctaNombre,0))),"⚠ Destino no registrado",IF(AND(P15="Pago tarjeta",AE15<>"Tarjeta de crédito"),"⚠ El destino debe ser tarjeta de crédito",IF(AND(P15="Gasto",E15="Depósitos y retiros"),"⚠ Usa tipo Transferencia",IF(AND(P15="Resultado trading",AD15<>"Cuenta de trading"),"⚠ Usa una cuenta de trading",IF(AND(G15<=0,P15<>"Ajuste",P15<>"Resultado trading"),"⚠ El monto debe ser positivo","✓"))))))))))))))) | P15: =IF(OR(B15="",G15=""),"",IF(C15="","Gasto",C15)) | Q15: =IF(P15="","",IF(J15<>"",J15,CuentaPred&"")) | R15: =IF(P15="","",IF(ISNUMBER(I15),I15,TasaUSD)) | S15: =IF(P15="","",IF(H15="USD",G15*R15,G15)) | T15: =IF(P15="","",IF(H15="USD",G15,IF(R15>0,G15/R15,0))) | U15: =IF(P15="","",IF(P15="Gasto",S15,IF(P15="Reembolso",-S15,0))) | V15: =IF(P15="","",IF(P15="Ingreso",S15,0)) | W15: =IF(P15="","",IF(P15="Resultado trading",S15,0)) | X15: =IF(OR(P15="Gasto",P15="Reembolso"),IF(M15<>"",M15,IFERROR(INDEX(catClasif,MATCH(D15&"|"&E15,catClave,0))&"","Variable")),"") | Y15: =IF(P15="","",IFERROR(INDEX(catGrupo,MATCH(D15&"|"&E15,catClave,0))&"","")) | Z15: =IF(P15="","",WEEKDAY(B15,2)) | AA15: =IF(P15="","",IF(AND(P15="Gasto",X15="Variable",D15<>catTrading,S15>0,S15<=Umbral),1,0)) | AB15: =IF(OR(P15="",Q15=""),"",IFERROR(IF(INDEX(ctaVinc,MATCH(Q15,ctaNombre,0))&""<>"",INDEX(ctaVinc,MATCH(Q15,ctaNombre,0))&"",Q15),Q15)) | AC15: =IF(OR(K15="",AND(P15<>"Transferencia",P15<>"Pago tarjeta")),"",IFERROR(IF(INDEX(ctaVinc,MATCH(K15,ctaNombre,0))&""<>"",INDEX(ctaVinc,MATCH(K15,ctaNombre,0))&"",K15),K15)) | AD15: =IF(AB15="","",IFERROR(INDEX(ctaTipo,MATCH(AB15,ctaNombre,0))&"","")) | AE15: =IF(AC15="","",IFERROR(INDEX(ctaTipo,MATCH(AC15,ctaNombre,0))&"","")) | AF15: =IF(OR(P15="",AB15=""),"",IF(OR(P15="Gasto",P15="Transferencia",P15="Pago tarjeta"),-1,1)*IF(IFERROR(INDEX(ctaMoneda,MATCH(AB15,ctaNombre,0))&"","DOP")="USD",T15,S15)) | AG15: =IF(AC15="","",IF(IFERROR(INDEX(ctaMoneda,MATCH(AC15,ctaNombre,0))&"","DOP")="USD",T15,S15)) | AH15: =IF(P15="","",IF(AND(AD15<>"",COUNTIFS(tcTipo,AD15,tcLiq,"Sí")>0),IF(OR(P15="Gasto",P15="Transferencia",P15="Pago tarjeta"),-1,1)*S15,0)+IF(AND(AE15<>"",COUNTIFS(tcTipo,AE15,tcLiq,"Sí")>0),S15,0)) | AI15: =IF(OR(L15="",P15=""),"",IF(COUNTIFS(L$6:L15,L15,P$6:P15,"?*")=1,MAX(AI$5:AI14)+1,""))
B16: 46240 | C16: Gasto | D16: Alimentación | E16: Desayunos comprados | F16: DEMO · Desayuno en la oficina | G16: 220 | H16: DOP | J16: Efectivo | L16: Cafetería del trabajo | N16: DEMOSTRACIÓN | O16: =IF(AND(B16="",G16="",C16="",D16="",J16=""),"",IF(B16="","⚠ Falta fecha",IF(G16="","⚠ Falta monto",IF(Q16="","⚠ Falta cuenta",IF(ISNA(MATCH(Q16,ctaNombre,0)),"⚠ Cuenta no registrada",IF(AND(OR(P16="Gasto",P16="Reembolso"),D16=""),"⚠ Falta categoría",IF(AND(D16<>"",E16<>"",ISNA(MATCH(D16&"|"&E16,catClave,0))),"⚠ Subcategoría no corresponde",IF(AND(OR(P16="Transferencia",P16="Pago tarjeta"),K16=""),"⚠ Falta cuenta destino",IF(AND(K16<>"",P16<>"Transferencia",P16<>"Pago tarjeta"),"⚠ Destino solo aplica a transferencias",IF(AND(K16<>"",K16=Q16),"⚠ Origen igual a destino",IF(AND(K16<>"",ISNA(MATCH(K16,ctaNombre,0))),"⚠ Destino no registrado",IF(AND(P16="Pago tarjeta",AE16<>"Tarjeta de crédito"),"⚠ El destino debe ser tarjeta de crédito",IF(AND(P16="Gasto",E16="Depósitos y retiros"),"⚠ Usa tipo Transferencia",IF(AND(P16="Resultado trading",AD16<>"Cuenta de trading"),"⚠ Usa una cuenta de trading",IF(AND(G16<=0,P16<>"Ajuste",P16<>"Resultado trading"),"⚠ El monto debe ser positivo","✓"))))))))))))))) | P16: =IF(OR(B16="",G16=""),"",IF(C16="","Gasto",C16)) | Q16: =IF(P16="","",IF(J16<>"",J16,CuentaPred&"")) | R16: =IF(P16="","",IF(ISNUMBER(I16),I16,TasaUSD)) | S16: =IF(P16="","",IF(H16="USD",G16*R16,G16)) | T16: =IF(P16="","",IF(H16="USD",G16,IF(R16>0,G16/R16,0))) | U16: =IF(P16="","",IF(P16="Gasto",S16,IF(P16="Reembolso",-S16,0))) | V16: =IF(P16="","",IF(P16="Ingreso",S16,0)) | W16: =IF(P16="","",IF(P16="Resultado trading",S16,0)) | X16: =IF(OR(P16="Gasto",P16="Reembolso"),IF(M16<>"",M16,IFERROR(INDEX(catClasif,MATCH(D16&"|"&E16,catClave,0))&"","Variable")),"") | Y16: =IF(P16="","",IFERROR(INDEX(catGrupo,MATCH(D16&"|"&E16,catClave,0))&"","")) | Z16: =IF(P16="","",WEEKDAY(B16,2)) | AA16: =IF(P16="","",IF(AND(P16="Gasto",X16="Variable",D16<>catTrading,S16>0,S16<=Umbral),1,0)) | AB16: =IF(OR(P16="",Q16=""),"",IFERROR(IF(INDEX(ctaVinc,MATCH(Q16,ctaNombre,0))&""<>"",INDEX(ctaVinc,MATCH(Q16,ctaNombre,0))&"",Q16),Q16)) | AC16: =IF(OR(K16="",AND(P16<>"Transferencia",P16<>"Pago tarjeta")),"",IFERROR(IF(INDEX(ctaVinc,MATCH(K16,ctaNombre,0))&""<>"",INDEX(ctaVinc,MATCH(K16,ctaNombre,0))&"",K16),K16)) | AD16: =IF(AB16="","",IFERROR(INDEX(ctaTipo,MATCH(AB16,ctaNombre,0))&"","")) | AE16: =IF(AC16="","",IFERROR(INDEX(ctaTipo,MATCH(AC16,ctaNombre,0))&"","")) | AF16: =IF(OR(P16="",AB16=""),"",IF(OR(P16="Gasto",P16="Transferencia",P16="Pago tarjeta"),-1,1)*IF(IFERROR(INDEX(ctaMoneda,MATCH(AB16,ctaNombre,0))&"","DOP")="USD",T16,S16)) | AG16: =IF(AC16="","",IF(IFERROR(INDEX(ctaMoneda,MATCH(AC16,ctaNombre,0))&"","DOP")="USD",T16,S16)) | AH16: =IF(P16="","",IF(AND(AD16<>"",COUNTIFS(tcTipo,AD16,tcLiq,"Sí")>0),IF(OR(P16="Gasto",P16="Transferencia",P16="Pago tarjeta"),-1,1)*S16,0)+IF(AND(AE16<>"",COUNTIFS(tcTipo,AE16,tcLiq,"Sí")>0),S16,0)) | AI16: =IF(OR(L16="",P16=""),"",IF(COUNTIFS(L$6:L16,L16,P$6:P16,"?*")=1,MAX(AI$5:AI15)+1,""))
B17: 46240 | C17: Gasto | D17: Alimentación | E17: Almuerzos laborales | F17: DEMO · Almuerzo laboral | G17: 475 | H17: DOP | J17: Billetera digital | L17: Comedor ejecutivo | N17: DEMOSTRACIÓN | O17: =IF(AND(B17="",G17="",C17="",D17="",J17=""),"",IF(B17="","⚠ Falta fecha",IF(G17="","⚠ Falta monto",IF(Q17="","⚠ Falta cuenta",IF(ISNA(MATCH(Q17,ctaNombre,0)),"⚠ Cuenta no registrada",IF(AND(OR(P17="Gasto",P17="Reembolso"),D17=""),"⚠ Falta categoría",IF(AND(D17<>"",E17<>"",ISNA(MATCH(D17&"|"&E17,catClave,0))),"⚠ Subcategoría no corresponde",IF(AND(OR(P17="Transferencia",P17="Pago tarjeta"),K17=""),"⚠ Falta cuenta destino",IF(AND(K17<>"",P17<>"Transferencia",P17<>"Pago tarjeta"),"⚠ Destino solo aplica a transferencias",IF(AND(K17<>"",K17=Q17),"⚠ Origen igual a destino",IF(AND(K17<>"",ISNA(MATCH(K17,ctaNombre,0))),"⚠ Destino no registrado",IF(AND(P17="Pago tarjeta",AE17<>"Tarjeta de crédito"),"⚠ El destino debe ser tarjeta de crédito",IF(AND(P17="Gasto",E17="Depósitos y retiros"),"⚠ Usa tipo Transferencia",IF(AND(P17="Resultado trading",AD17<>"Cuenta de trading"),"⚠ Usa una cuenta de trading",IF(AND(G17<=0,P17<>"Ajuste",P17<>"Resultado trading"),"⚠ El monto debe ser positivo","✓"))))))))))))))) | P17: =IF(OR(B17="",G17=""),"",IF(C17="","Gasto",C17)) | Q17: =IF(P17="","",IF(J17<>"",J17,CuentaPred&"")) | R17: =IF(P17="","",IF(ISNUMBER(I17),I17,TasaUSD)) | S17: =IF(P17="","",IF(H17="USD",G17*R17,G17)) | T17: =IF(P17="","",IF(H17="USD",G17,IF(R17>0,G17/R17,0))) | U17: =IF(P17="","",IF(P17="Gasto",S17,IF(P17="Reembolso",-S17,0))) | V17: =IF(P17="","",IF(P17="Ingreso",S17,0)) | W17: =IF(P17="","",IF(P17="Resultado trading",S17,0)) | X17: =IF(OR(P17="Gasto",P17="Reembolso"),IF(M17<>"",M17,IFERROR(INDEX(catClasif,MATCH(D17&"|"&E17,catClave,0))&"","Variable")),"") | Y17: =IF(P17="","",IFERROR(INDEX(catGrupo,MATCH(D17&"|"&E17,catClave,0))&"","")) | Z17: =IF(P17="","",WEEKDAY(B17,2)) | AA17: =IF(P17="","",IF(AND(P17="Gasto",X17="Variable",D17<>catTrading,S17>0,S17<=Umbral),1,0)) | AB17: =IF(OR(P17="",Q17=""),"",IFERROR(IF(INDEX(ctaVinc,MATCH(Q17,ctaNombre,0))&""<>"",INDEX(ctaVinc,MATCH(Q17,ctaNombre,0))&"",Q17),Q17)) | AC17: =IF(OR(K17="",AND(P17<>"Transferencia",P17<>"Pago tarjeta")),"",IFERROR(IF(INDEX(ctaVinc,MATCH(K17,ctaNombre,0))&""<>"",INDEX(ctaVinc,MATCH(K17,ctaNombre,0))&"",K17),K17)) | AD17: =IF(AB17="","",IFERROR(INDEX(ctaTipo,MATCH(AB17,ctaNombre,0))&"","")) | AE17: =IF(AC17="","",IFERROR(INDEX(ctaTipo,MATCH(AC17,ctaNombre,0))&"","")) | AF17: =IF(OR(P17="",AB17=""),"",IF(OR(P17="Gasto",P17="Transferencia",P17="Pago tarjeta"),-1,1)*IF(IFERROR(INDEX(ctaMoneda,MATCH(AB17,ctaNombre,0))&"","DOP")="USD",T17,S17)) | AG17: =IF(AC17="","",IF(IFERROR(INDEX(ctaMoneda,MATCH(AC17,ctaNombre,0))&"","DOP")="USD",T17,S17)) | AH17: =IF(P17="","",IF(AND(AD17<>"",COUNTIFS(tcTipo,AD17,tcLiq,"Sí")>0),IF(OR(P17="Gasto",P17="Transferencia",P17="Pago tarjeta"),-1,1)*S17,0)+IF(AND(AE17<>"",COUNTIFS(tcTipo,AE17,tcLiq,"Sí")>0),S17,0)) | AI17: =IF(OR(L17="",P17=""),"",IF(COUNTIFS(L$6:L17,L17,P$6:P17,"?*")=1,MAX(AI$5:AI16)+1,""))
B18: 46240 | C18: Gasto | D18: Transporte y vehículo | E18: Parqueos y peajes | F18: DEMO · Parqueo | G18: 100 | H18: DOP | J18: Efectivo | L18: Parqueo centro | N18: DEMOSTRACIÓN | O18: =IF(AND(B18="",G18="",C18="",D18="",J18=""),"",IF(B18="","⚠ Falta fecha",IF(G18="","⚠ Falta monto",IF(Q18="","⚠ Falta cuenta",IF(ISNA(MATCH(Q18,ctaNombre,0)),"⚠ Cuenta no registrada",IF(AND(OR(P18="Gasto",P18="Reembolso"),D18=""),"⚠ Falta categoría",IF(AND(D18<>"",E18<>"",ISNA(MATCH(D18&"|"&E18,catClave,0))),"⚠ Subcategoría no corresponde",IF(AND(OR(P18="Transferencia",P18="Pago tarjeta"),K18=""),"⚠ Falta cuenta destino",IF(AND(K18<>"",P18<>"Transferencia",P18<>"Pago tarjeta"),"⚠ Destino solo aplica a transferencias",IF(AND(K18<>"",K18=Q18),"⚠ Origen igual a destino",IF(AND(K18<>"",ISNA(MATCH(K18,ctaNombre,0))),"⚠ Destino no registrado",IF(AND(P18="Pago tarjeta",AE18<>"Tarjeta de crédito"),"⚠ El destino debe ser tarjeta de crédito",IF(AND(P18="Gasto",E18="Depósitos y retiros"),"⚠ Usa tipo Transferencia",IF(AND(P18="Resultado trading",AD18<>"Cuenta de trading"),"⚠ Usa una cuenta de trading",IF(AND(G18<=0,P18<>"Ajuste",P18<>"Resultado trading"),"⚠ El monto debe ser positivo","✓"))))))))))))))) | P18: =IF(OR(B18="",G18=""),"",IF(C18="","Gasto",C18)) | Q18: =IF(P18="","",IF(J18<>"",J18,CuentaPred&"")) | R18: =IF(P18="","",IF(ISNUMBER(I18),I18,TasaUSD)) | S18: =IF(P18="","",IF(H18="USD",G18*R18,G18)) | T18: =IF(P18="","",IF(H18="USD",G18,IF(R18>0,G18/R18,0))) | U18: =IF(P18="","",IF(P18="Gasto",S18,IF(P18="Reembolso",-S18,0))) | V18: =IF(P18="","",IF(P18="Ingreso",S18,0)) | W18: =IF(P18="","",IF(P18="Resultado trading",S18,0)) | X18: =IF(OR(P18="Gasto",P18="Reembolso"),IF(M18<>"",M18,IFERROR(INDEX(catClasif,MATCH(D18&"|"&E18,catClave,0))&"","Variable")),"") | Y18: =IF(P18="","",IFERROR(INDEX(catGrupo,MATCH(D18&"|"&E18,catClave,0))&"","")) | Z18: =IF(P18="","",WEEKDAY(B18,2)) | AA18: =IF(P18="","",IF(AND(P18="Gasto",X18="Variable",D18<>catTrading,S18>0,S18<=Umbral),1,0)) | AB18: =IF(OR(P18="",Q18=""),"",IFERROR(IF(INDEX(ctaVinc,MATCH(Q18,ctaNombre,0))&""<>"",INDEX(ctaVinc,MATCH(Q18,ctaNombre,0))&"",Q18),Q18)) | AC18: =IF(OR(K18="",AND(P18<>"Transferencia",P18<>"Pago tarjeta")),"",IFERROR(IF(INDEX(ctaVinc,MATCH(K18,ctaNombre,0))&""<>"",INDEX(ctaVinc,MATCH(K18,ctaNombre,0))&"",K18),K18)) | AD18: =IF(AB18="","",IFERROR(INDEX(ctaTipo,MATCH(AB18,ctaNombre,0))&"","")) | AE18: =IF(AC18="","",IFERROR(INDEX(ctaTipo,MATCH(AC18,ctaNombre,0))&"","")) | AF18: =IF(OR(P18="",AB18=""),"",IF(OR(P18="Gasto",P18="Transferencia",P18="Pago tarjeta"),-1,1)*IF(IFERROR(INDEX(ctaMoneda,MATCH(AB18,ctaNombre,0))&"","DOP")="USD",T18,S18)) | AG18: =IF(AC18="","",IF(IFERROR(INDEX(ctaMoneda,MATCH(AC18,ctaNombre,0))&"","DOP")="USD",T18,S18)) | AH18: =IF(P18="","",IF(AND(AD18<>"",COUNTIFS(tcTipo,AD18,tcLiq,"Sí")>0),IF(OR(P18="Gasto",P18="Transferencia",P18="Pago tarjeta"),-1,1)*S18,0)+IF(AND(AE18<>"",COUNTIFS(tcTipo,AE18,tcLiq,"Sí")>0),S18,0)) | AI18: =IF(OR(L18="",P18=""),"",IF(COUNTIFS(L$6:L18,L18,P$6:P18,"?*")=1,MAX(AI$5:AI17)+1,""))
B19: 46240 | C19: Transferencia | D19: Trading y actividades financieras | E19: Depósitos y retiros | F19: DEMO · Depósito a cuenta de trading | G19: 15750 | H19: DOP | I19: 63 | J19: Banco principal | K19: Cuenta de trading | N19: DEMOSTRACIÓN | O19: =IF(AND(B19="",G19="",C19="",D19="",J19=""),"",IF(B19="","⚠ Falta fecha",IF(G19="","⚠ Falta monto",IF(Q19="","⚠ Falta cuenta",IF(ISNA(MATCH(Q19,ctaNombre,0)),"⚠ Cuenta no registrada",IF(AND(OR(P19="Gasto",P19="Reembolso"),D19=""),"⚠ Falta categoría",IF(AND(D19<>"",E19<>"",ISNA(MATCH(D19&"|"&E19,catClave,0))),"⚠ Subcategoría no corresponde",IF(AND(OR(P19="Transferencia",P19="Pago tarjeta"),K19=""),"⚠ Falta cuenta destino",IF(AND(K19<>"",P19<>"Transferencia",P19<>"Pago tarjeta"),"⚠ Destino solo aplica a transferencias",IF(AND(K19<>"",K19=Q19),"⚠ Origen igual a destino",IF(AND(K19<>"",ISNA(MATCH(K19,ctaNombre,0))),"⚠ Destino no registrado",IF(AND(P19="Pago tarjeta",AE19<>"Tarjeta de crédito"),"⚠ El destino debe ser tarjeta de crédito",IF(AND(P19="Gasto",E19="Depósitos y retiros"),"⚠ Usa tipo Transferencia",IF(AND(P19="Resultado trading",AD19<>"Cuenta de trading"),"⚠ Usa una cuenta de trading",IF(AND(G19<=0,P19<>"Ajuste",P19<>"Resultado trading"),"⚠ El monto debe ser positivo","✓"))))))))))))))) | P19: =IF(OR(B19="",G19=""),"",IF(C19="","Gasto",C19)) | Q19: =IF(P19="","",IF(J19<>"",J19,CuentaPred&"")) | R19: =IF(P19="","",IF(ISNUMBER(I19),I19,TasaUSD)) | S19: =IF(P19="","",IF(H19="USD",G19*R19,G19)) | T19: =IF(P19="","",IF(H19="USD",G19,IF(R19>0,G19/R19,0))) | U19: =IF(P19="","",IF(P19="Gasto",S19,IF(P19="Reembolso",-S19,0))) | V19: =IF(P19="","",IF(P19="Ingreso",S19,0)) | W19: =IF(P19="","",IF(P19="Resultado trading",S19,0)) | X19: =IF(OR(P19="Gasto",P19="Reembolso"),IF(M19<>"",M19,IFERROR(INDEX(catClasif,MATCH(D19&"|"&E19,catClave,0))&"","Variable")),"") | Y19: =IF(P19="","",IFERROR(INDEX(catGrupo,MATCH(D19&"|"&E19,catClave,0))&"","")) | Z19: =IF(P19="","",WEEKDAY(B19,2)) | AA19: =IF(P19="","",IF(AND(P19="Gasto",X19="Variable",D19<>catTrading,S19>0,S19<=Umbral),1,0)) | AB19: =IF(OR(P19="",Q19=""),"",IFERROR(IF(INDEX(ctaVinc,MATCH(Q19,ctaNombre,0))&""<>"",INDEX(ctaVinc,MATCH(Q19,ctaNombre,0))&"",Q19),Q19)) | AC19: =IF(OR(K19="",AND(P19<>"Transferencia",P19<>"Pago tarjeta")),"",IFERROR(IF(INDEX(ctaVinc,MATCH(K19,ctaNombre,0))&""<>"",INDEX(ctaVinc,MATCH(K19,ctaNombre,0))&"",K19),K19)) | AD19: =IF(AB19="","",IFERROR(INDEX(ctaTipo,MATCH(AB19,ctaNombre,0))&"","")) | AE19: =IF(AC19="","",IFERROR(INDEX(ctaTipo,MATCH(AC19,ctaNombre,0))&"","")) | AF19: =IF(OR(P19="",AB19=""),"",IF(OR(P19="Gasto",P19="Transferencia",P19="Pago tarjeta"),-1,1)*IF(IFERROR(INDEX(ctaMoneda,MATCH(AB19,ctaNombre,0))&"","DOP")="USD",T19,S19)) | AG19: =IF(AC19="","",IF(IFERROR(INDEX(ctaMoneda,MATCH(AC19,ctaNombre,0))&"","DOP")="USD",T19,S19)) | AH19: =IF(P19="","",IF(AND(AD19<>"",COUNTIFS(tcTipo,AD19,tcLiq,"Sí")>0),IF(OR(P19="Gasto",P19="Transferencia",P19="Pago tarjeta"),-1,1)*S19,0)+IF(AND(AE19<>"",COUNTIFS(tcTipo,AE19,tcLiq,"Sí")>0),S19,0)) | AI19: =IF(OR(L19="",P19=""),"",IF(COUNTIFS(L$6:L19,L19,P$6:P19,"?*")=1,MAX(AI$5:AI18)+1,""))
B20: 46241 | C20: Gasto | D20: Alimentación | E20: Almuerzos laborales | F20: DEMO · Almuerzo laboral | G20: 575 | H20: DOP | J20: Billetera digital | L20: Comedor ejecutivo | N20: DEMOSTRACIÓN | O20: =IF(AND(B20="",G20="",C20="",D20="",J20=""),"",IF(B20="","⚠ Falta fecha",IF(G20="","⚠ Falta monto",IF(Q20="","⚠ Falta cuenta",IF(ISNA(MATCH(Q20,ctaNombre,0)),"⚠ Cuenta no registrada",IF(AND(OR(P20="Gasto",P20="Reembolso"),D20=""),"⚠ Falta categoría",IF(AND(D20<>"",E20<>"",ISNA(MATCH(D20&"|"&E20,catClave,0))),"⚠ Subcategoría no corresponde",IF(AND(OR(P20="Transferencia",P20="Pago tarjeta"),K20=""),"⚠ Falta cuenta destino",IF(AND(K20<>"",P20<>"Transferencia",P20<>"Pago tarjeta"),"⚠ Destino solo aplica a transferencias",IF(AND(K20<>"",K20=Q20),"⚠ Origen igual a destino",IF(AND(K20<>"",ISNA(MATCH(K20,ctaNombre,0))),"⚠ Destino no registrado",IF(AND(P20="Pago tarjeta",AE20<>"Tarjeta de crédito"),"⚠ El destino debe ser tarjeta de crédito",IF(AND(P20="Gasto",E20="Depósitos y retiros"),"⚠ Usa tipo Transferencia",IF(AND(P20="Resultado trading",AD20<>"Cuenta de trading"),"⚠ Usa una cuenta de trading",IF(AND(G20<=0,P20<>"Ajuste",P20<>"Resultado trading"),"⚠ El monto debe ser positivo","✓"))))))))))))))) | P20: =IF(OR(B20="",G20=""),"",IF(C20="","Gasto",C20)) | Q20: =IF(P20="","",IF(J20<>"",J20,CuentaPred&"")) | R20: =IF(P20="","",IF(ISNUMBER(I20),I20,TasaUSD)) | S20: =IF(P20="","",IF(H20="USD",G20*R20,G20)) | T20: =IF(P20="","",IF(H20="USD",G20,IF(R20>0,G20/R20,0))) | U20: =IF(P20="","",IF(P20="Gasto",S20,IF(P20="Reembolso",-S20,0))) | V20: =IF(P20="","",IF(P20="Ingreso",S20,0)) | W20: =IF(P20="","",IF(P20="Resultado trading",S20,0)) | X20: =IF(OR(P20="Gasto",P20="Reembolso"),IF(M20<>"",M20,IFERROR(INDEX(catClasif,MATCH(D20&"|"&E20,catClave,0))&"","Variable")),"") | Y20: =IF(P20="","",IFERROR(INDEX(catGrupo,MATCH(D20&"|"&E20,catClave,0))&"","")) | Z20: =IF(P20="","",WEEKDAY(B20,2)) | AA20: =IF(P20="","",IF(AND(P20="Gasto",X20="Variable",D20<>catTrading,S20>0,S20<=Umbral),1,0)) | AB20: =IF(OR(P20="",Q20=""),"",IFERROR(IF(INDEX(ctaVinc,MATCH(Q20,ctaNombre,0))&""<>"",INDEX(ctaVinc,MATCH(Q20,ctaNombre,0))&"",Q20),Q20)) | AC20: =IF(OR(K20="",AND(P20<>"Transferencia",P20<>"Pago tarjeta")),"",IFERROR(IF(INDEX(ctaVinc,MATCH(K20,ctaNombre,0))&""<>"",INDEX(ctaVinc,MATCH(K20,ctaNombre,0))&"",K20),K20)) | AD20: =IF(AB20="","",IFERROR(INDEX(ctaTipo,MATCH(AB20,ctaNombre,0))&"","")) | AE20: =IF(AC20="","",IFERROR(INDEX(ctaTipo,MATCH(AC20,ctaNombre,0))&"","")) | AF20: =IF(OR(P20="",AB20=""),"",IF(OR(P20="Gasto",P20="Transferencia",P20="Pago tarjeta"),-1,1)*IF(IFERROR(INDEX(ctaMoneda,MATCH(AB20,ctaNombre,0))&"","DOP")="USD",T20,S20)) | AG20: =IF(AC20="","",IF(IFERROR(INDEX(ctaMoneda,MATCH(AC20,ctaNombre,0))&"","DOP")="USD",T20,S20)) | AH20: =IF(P20="","",IF(AND(AD20<>"",COUNTIFS(tcTipo,AD20,tcLiq,"Sí")>0),IF(OR(P20="Gasto",P20="Transferencia",P20="Pago tarjeta"),-1,1)*S20,0)+IF(AND(AE20<>"",COUNTIFS(tcTipo,AE20,tcLiq,"Sí")>0),S20,0)) | AI20: =IF(OR(L20="",P20=""),"",IF(COUNTIFS(L$6:L20,L20,P$6:P20,"?*")=1,MAX(AI$5:AI19)+1,""))
B21: 46241 | C21: Gasto | D21: Alimentación | E21: Bebidas, snacks y otros consumos | F21: DEMO · Jugo y galletas | G21: 130 | H21: DOP | J21: Billetera digital | L21: Colmado del barrio | N21: DEMOSTRACIÓN | O21: =IF(AND(B21="",G21="",C21="",D21="",J21=""),"",IF(B21="","⚠ Falta fecha",IF(G21="","⚠ Falta monto",IF(Q21="","⚠ Falta cuenta",IF(ISNA(MATCH(Q21,ctaNombre,0)),"⚠ Cuenta no registrada",IF(AND(OR(P21="Gasto",P21="Reembolso"),D21=""),"⚠ Falta categoría",IF(AND(D21<>"",E21<>"",ISNA(MATCH(D21&"|"&E21,catClave,0))),"⚠ Subcategoría no corresponde",IF(AND(OR(P21="Transferencia",P21="Pago tarjeta"),K21=""),"⚠ Falta cuenta destino",IF(AND(K21<>"",P21<>"Transferencia",P21<>"Pago tarjeta"),"⚠ Destino solo aplica a transferencias",IF(AND(K21<>"",K21=Q21),"⚠ Origen igual a destino",IF(AND(K21<>"",ISNA(MATCH(K21,ctaNombre,0))),"⚠ Destino no registrado",IF(AND(P21="Pago tarjeta",AE21<>"Tarjeta de crédito"),"⚠ El destino debe ser tarjeta de crédito",IF(AND(P21="Gasto",E21="Depósitos y retiros"),"⚠ Usa tipo Transferencia",IF(AND(P21="Resultado trading",AD21<>"Cuenta de trading"),"⚠ Usa una cuenta de trading",IF(AND(G21<=0,P21<>"Ajuste",P21<>"Resultado trading"),"⚠ El monto debe ser positivo","✓"))))))))))))))) | P21: =IF(OR(B21="",G21=""),"",IF(C21="","Gasto",C21)) | Q21: =IF(P21="","",IF(J21<>"",J21,CuentaPred&"")) | R21: =IF(P21="","",IF(ISNUMBER(I21),I21,TasaUSD)) | S21: =IF(P21="","",IF(H21="USD",G21*R21,G21)) | T21: =IF(P21="","",IF(H21="USD",G21,IF(R21>0,G21/R21,0))) | U21: =IF(P21="","",IF(P21="Gasto",S21,IF(P21="Reembolso",-S21,0))) | V21: =IF(P21="","",IF(P21="Ingreso",S21,0)) | W21: =IF(P21="","",IF(P21="Resultado trading",S21,0)) | X21: =IF(OR(P21="Gasto",P21="Reembolso"),IF(M21<>"",M21,IFERROR(INDEX(catClasif,MATCH(D21&"|"&E21,catClave,0))&"","Variable")),"") | Y21: =IF(P21="","",IFERROR(INDEX(catGrupo,MATCH(D21&"|"&E21,catClave,0))&"","")) | Z21: =IF(P21="","",WEEKDAY(B21,2)) | AA21: =IF(P21="","",IF(AND(P21="Gasto",X21="Variable",D21<>catTrading,S21>0,S21<=Umbral),1,0)) | AB21: =IF(OR(P21="",Q21=""),"",IFERROR(IF(INDEX(ctaVinc,MATCH(Q21,ctaNombre,0))&""<>"",INDEX(ctaVinc,MATCH(Q21,ctaNombre,0))&"",Q21),Q21)) | AC21: =IF(OR(K21="",AND(P21<>"Transferencia",P21<>"Pago tarjeta")),"",IFERROR(IF(INDEX(ctaVinc,MATCH(K21,ctaNombre,0))&""<>"",INDEX(ctaVinc,MATCH(K21,ctaNombre,0))&"",K21),K21)) | AD21: =IF(AB21="","",IFERROR(INDEX(ctaTipo,MATCH(AB21,ctaNombre,0))&"","")) | AE21: =IF(AC21="","",IFERROR(INDEX(ctaTipo,MATCH(AC21,ctaNombre,0))&"","")) | AF21: =IF(OR(P21="",AB21=""),"",IF(OR(P21="Gasto",P21="Transferencia",P21="Pago tarjeta"),-1,1)*IF(IFERROR(INDEX(ctaMoneda,MATCH(AB21,ctaNombre,0))&"","DOP")="USD",T21,S21)) | AG21: =IF(AC21="","",IF(IFERROR(INDEX(ctaMoneda,MATCH(AC21,ctaNombre,0))&"","DOP")="USD",T21,S21)) | AH21: =IF(P21="","",IF(AND(AD21<>"",COUNTIFS(tcTipo,AD21,tcLiq,"Sí")>0),IF(OR(P21="Gasto",P21="Transferencia",P21="Pago tarjeta"),-1,1)*S21,0)+IF(AND(AE21<>"",COUNTIFS(tcTipo,AE21,tcLiq,"Sí")>0),S21,0)) | AI21: =IF(OR(L21="",P21=""),"",IF(COUNTIFS(L$6:L21,L21,P$6:P21,"?*")=1,MAX(AI$5:AI20)+1,""))
B22: 46241 | C22: Gasto | D22: Trading y actividades financieras | E22: Evaluaciones y cuentas de trading | F22: DEMO · Evaluación de cuenta fondeada | G22: 150 | H22: USD | J22: Tarjeta de crédito | L22: Firma de evaluación | N22: DEMOSTRACIÓN | O22: =IF(AND(B22="",G22="",C22="",D22="",J22=""),"",IF(B22="","⚠ Falta fecha",IF(G22="","⚠ Falta monto",IF(Q22="","⚠ Falta cuenta",IF(ISNA(MATCH(Q22,ctaNombre,0)),"⚠ Cuenta no registrada",IF(AND(OR(P22="Gasto",P22="Reembolso"),D22=""),"⚠ Falta categoría",IF(AND(D22<>"",E22<>"",ISNA(MATCH(D22&"|"&E22,catClave,0))),"⚠ Subcategoría no corresponde",IF(AND(OR(P22="Transferencia",P22="Pago tarjeta"),K22=""),"⚠ Falta cuenta destino",IF(AND(K22<>"",P22<>"Transferencia",P22<>"Pago tarjeta"),"⚠ Destino solo aplica a transferencias",IF(AND(K22<>"",K22=Q22),"⚠ Origen igual a destino",IF(AND(K22<>"",ISNA(MATCH(K22,ctaNombre,0))),"⚠ Destino no registrado",IF(AND(P22="Pago tarjeta",AE22<>"Tarjeta de crédito"),"⚠ El destino debe ser tarjeta de crédito",IF(AND(P22="Gasto",E22="Depósitos y retiros"),"⚠ Usa tipo Transferencia",IF(AND(P22="Resultado trading",AD22<>"Cuenta de trading"),"⚠ Usa una cuenta de trading",IF(AND(G22<=0,P22<>"Ajuste",P22<>"Resultado trading"),"⚠ El monto debe ser positivo","✓"))))))))))))))) | P22: =IF(OR(B22="",G22=""),"",IF(C22="","Gasto",C22)) | Q22: =IF(P22="","",IF(J22<>"",J22,CuentaPred&"")) | R22: =IF(P22="","",IF(ISNUMBER(I22),I22,TasaUSD)) | S22: =IF(P22="","",IF(H22="USD",G22*R22,G22)) | T22: =IF(P22="","",IF(H22="USD",G22,IF(R22>0,G22/R22,0))) | U22: =IF(P22="","",IF(P22="Gasto",S22,IF(P22="Reembolso",-S22,0))) | V22: =IF(P22="","",IF(P22="Ingreso",S22,0)) | W22: =IF(P22="","",IF(P22="Resultado trading",S22,0)) | X22: =IF(OR(P22="Gasto",P22="Reembolso"),IF(M22<>"",M22,IFERROR(INDEX(catClasif,MATCH(D22&"|"&E22,catClave,0))&"","Variable")),"") | Y22: =IF(P22="","",IFERROR(INDEX(catGrupo,MATCH(D22&"|"&E22,catClave,0))&"","")) | Z22: =IF(P22="","",WEEKDAY(B22,2)) | AA22: =IF(P22="","",IF(AND(P22="Gasto",X22="Variable",D22<>catTrading,S22>0,S22<=Umbral),1,0)) | AB22: =IF(OR(P22="",Q22=""),"",IFERROR(IF(INDEX(ctaVinc,MATCH(Q22,ctaNombre,0))&""<>"",INDEX(ctaVinc,MATCH(Q22,ctaNombre,0))&"",Q22),Q22)) | AC22: =IF(OR(K22="",AND(P22<>"Transferencia",P22<>"Pago tarjeta")),"",IFERROR(IF(INDEX(ctaVinc,MATCH(K22,ctaNombre,0))&""<>"",INDEX(ctaVinc,MATCH(K22,ctaNombre,0))&"",K22),K22)) | AD22: =IF(AB22="","",IFERROR(INDEX(ctaTipo,MATCH(AB22,ctaNombre,0))&"","")) | AE22: =IF(AC22="","",IFERROR(INDEX(ctaTipo,MATCH(AC22,ctaNombre,0))&"","")) | AF22: =IF(OR(P22="",AB22=""),"",IF(OR(P22="Gasto",P22="Transferencia",P22="Pago tarjeta"),-1,1)*IF(IFERROR(INDEX(ctaMoneda,MATCH(AB22,ctaNombre,0))&"","DOP")="USD",T22,S22)) | AG22: =IF(AC22="","",IF(IFERROR(INDEX(ctaMoneda,MATCH(AC22,ctaNombre,0))&"","DOP")="USD",T22,S22)) | AH22: =IF(P22="","",IF(AND(AD22<>"",COUNTIFS(tcTipo,AD22,tcLiq,"Sí")>0),IF(OR(P22="Gasto",P22="Transferencia",P22="Pago tarjeta"),-1,1)*S22,0)+IF(AND(AE22<>"",COUNTIFS(tcTipo,AE22,tcLiq,"Sí")>0),S22,0)) | AI22: =IF(OR(L22="",P22=""),"",IF(COUNTIFS(L$6:L22,L22,P$6:P22,"?*")=1,MAX(AI$5:AI21)+1,""))
